
| distributed init (rank 3): env://, gpu 3
Error in sys.excepthook:
Traceback (most recent call last):
  File "/home/sooh/.conda/envs/myenv/lib/python3.8/site-packages/wandb/sdk/lib/exit_hooks.py", line 52, in exc_handler
    traceback.print_exception(exc_type, exc, tb)Exception in thread
  File "/home/sooh/.conda/envs/myenv/lib/python3.8/traceback.py", line 103, in print_exception
Thread-3    :
for line in TracebackException(
  File "/home/sooh/.conda/envs/myenv/lib/python3.8/traceback.py", line 508, in __init__
    self.stack = StackSummary.extract(
  File "/home/sooh/.conda/envs/myenv/lib/python3.8/traceback.py", line 353, in extract
Traceback (most recent call last):
      File "/home/sooh/.conda/envs/myenv/lib/python3.8/threading.py", line 932, in _bootstrap_inner
linecache.lazycache(filename, f.f_globals)
  File "/home/sooh/.conda/envs/myenv/lib/python3.8/linecache.py", line 161, in lazycache
    self.run()
  File "/home/sooh/.conda/envs/myenv/lib/python3.8/threading.py", line 870, in run
    if len(cache[filename]) == 1:
KeyboardInterrupt
self._target(*self._args, **self._kwargs)
Original exception was:
Traceback (most recent call last):
  File "/home/sooh/.conda/envs/myenv/lib/python3.8/site-packages/torch/utils/data/_utils/pin_memory.py", line 51, in _pin_memory_loop
  File "finetuning_hipe_prompt1.py", line 410, in <module>
    do_one_step()
main(args)  File "/home/sooh/.conda/envs/myenv/lib/python3.8/site-packages/torch/utils/data/_utils/pin_memory.py", line 28, in do_one_step
  File "finetuning_hipe_prompt1.py", line 367, in main
    r = in_queue.get(timeout=MP_STATUS_CHECK_INTERVAL)
  File "/home/sooh/.conda/envs/myenv/lib/python3.8/multiprocessing/queues.py", line 116, in get
    train_stats = train_one_epoch(
  File "/home/sooh/historical-adapters/alpaca_finetuning_v1/engine_finetuning.py", line 30, in train_one_epoch
    for data_iter_step, (examples, labels, example_mask) in enumerate(metric_logger.log_every(data_loader, print_freq, header)):
  File "/home/sooh/historical-adapters/alpaca_finetuning_v1/util/misc.py", line 144, in log_every
    for obj in iterable:
  File "/home/sooh/.conda/envs/myenv/lib/python3.8/site-packages/torch/utils/data/dataloader.py", line 633, in __next__
    data = self._next_data()
  File "/home/sooh/.conda/envs/myenv/lib/python3.8/site-packages/torch/utils/data/dataloader.py", line 1328, in _next_data
    return _ForkingPickler.loads(res)
  File "/home/sooh/.conda/envs/myenv/lib/python3.8/site-packages/torch/multiprocessing/reductions.py", line 307, in rebuild_storage_fd
        idx, data = self._get_data()fd = df.detach()
  File "/home/sooh/.conda/envs/myenv/lib/python3.8/site-packages/torch/utils/data/dataloader.py", line 1284, in _get_data
  File "/home/sooh/.conda/envs/myenv/lib/python3.8/multiprocessing/resource_sharer.py", line 57, in detach
        with _resource_sharer.get_connection(self._id) as conn:success, data = self._try_get_data()
  File "/home/sooh/.conda/envs/myenv/lib/python3.8/multiprocessing/resource_sharer.py", line 87, in get_connection
  File "/home/sooh/.conda/envs/myenv/lib/python3.8/site-packages/torch/utils/data/dataloader.py", line 1132, in _try_get_data
    c = Client(address, authkey=process.current_process().authkey)
  File "/home/sooh/.conda/envs/myenv/lib/python3.8/multiprocessing/connection.py", line 502, in Client
    data = self._data_queue.get(timeout=timeout)
      File "/home/sooh/.conda/envs/myenv/lib/python3.8/queue.py", line 179, in get
c = SocketClient(address)
  File "/home/sooh/.conda/envs/myenv/lib/python3.8/multiprocessing/connection.py", line 630, in SocketClient
    self.not_empty.wait(remaining)
s.connect(address)  File "/home/sooh/.conda/envs/myenv/lib/python3.8/threading.py", line 306, in wait
FileNotFoundError: [Errno 2] No such file or directory
gotit = waiter.acquire(True, timeout)
KeyboardInterrupt